<robot name="dumpUrdf">
	<link name="base">
		<inertial>
			<origin rpy="0 0 0" xyz="0 0 0" />
			<mass value="0.0001" />
			<inertia ixx="0.0001" ixy="0" ixz="0" iyy="0.0001" iyz="0" izz="0.0001" />
		</inertial>
	</link>
	<link name="root">
		<inertial>
			<origin rpy="0 0 0" xyz="0 0.086154 0" />
			<mass value="9.032258" />
			<inertia ixx="0.014252" ixy="0" ixz="0" iyy="0.014252" iyz="0" izz="0.014252" />
		</inertial>
		<collision>
			<origin rpy="0 0 0" xyz="0 0.086154 0" />
			<geometry>
				<sphere radius="0.110769" />
			</geometry>
		</collision>
	</link>
	<joint name="root" type="fixed">
		<parent link="base" />
		<child link="root" />
		<origin rpy="0 0 0" xyz="0 0 0" />
	</joint>
	<link name="spine">
		<inertial>
			<origin rpy="0 0 0" xyz="0 0.072615 0" />
			<mass value="6.021505" />
			<inertia ixx="0.010689" ixy="0" ixz="0" iyy="0.010689" iyz="0" izz="0.010689" />
		</inertial>
		<collision>
			<origin rpy="0 0 0" xyz="0 0.072615 0" />
			<geometry>
				<sphere radius="0.092308" />
			</geometry>
		</collision>
	</link>
	<joint name="spine" type="spherical">
		<parent link="root" />
		<child link="spine" />
		<origin rpy="0 0 0" xyz="0 0.145324 0" />
		<axis xyz="0 0 1" />
	</joint>
	<link name="chest">
		<inertial>
			<origin rpy="0 0 0" xyz="0 0.147692 0" />
			<mass value="21.075269" />
			<inertia ixx="0.03563" ixy="0" ixz="0" iyy="0.03563" iyz="0" izz="0.03563" />
		</inertial>
		<collision>
			<origin rpy="0 0 0" xyz="0 0.147692 0" />
			<geometry>
				<sphere radius="0.135385" />
			</geometry>
		</collision>
	</link>
	<joint name="chest" type="fixed">
		<parent link="spine" />
		<child link="chest" />
		<origin rpy="0 0 0" xyz="0 0.145324 0" />
	</joint>
	<link name="neck">
		<inertial>
			<origin rpy="0 0 0" xyz="0 0.215385 0" />
			<mass value="3.010753" />
			<inertia ixx="0.003563" ixy="0" ixz="0" iyy="0.003563" iyz="0" izz="0.003563" />
		</inertial>
		<collision>
			<origin rpy="0 0 0" xyz="0 0.215385 0" />
			<geometry>
				<sphere radius="0.126154" />
			</geometry>
		</collision>
	</link>
	<link name="head">
		<inertial>
			<origin rpy="0 0 0" xyz="0 0.06 0" />
			<mass value="3.387097" />
			<inertia ixx="0.002138" ixy="0" ixz="0" iyy="0.002138" iyz="0" izz="0.002138" />
		</inertial>
		<collision>
			<origin rpy="0 0 0" xyz="0 0.06 0" />
			<geometry>
				<sphere radius="0.036923" />
			</geometry>
		</collision>
		<visual>
			<origin rpy="0 0 0" xyz="0 0.06 0" />
			<geometry>
				<sphere radius="0.036923" />
			</geometry>
		</visual>
	</link>
	<joint name="neck" type="spherical">
		<parent link="chest" />
		<child link="neck" />
		<origin rpy="0 0 0" xyz="0 0.275562 0" />
		<axis xyz="0 0 1" />
	</joint>
	<joint name="head" type="fixed">
		<parent link="neck" />
		<child link="head" />
		<origin rpy="0 0 0" xyz="0 0.341538 0" />
	</joint>
	<link name="right_hip">
		<inertial>
			<origin rpy="0 0 0" xyz="0 -0.258462 0" />
			<mass value="6.774194" />
			<inertia ixx="0.007126" ixy="0" ixz="0" iyy="0.007126" iyz="0" izz="0.007126" />
		</inertial>
		<collision>
			<origin rpy="-1.570796 0 0" xyz="0 -0.258462 0" />
			<geometry>
				<capsule length="0.369231" radius="0.067692" />
			</geometry>
		</collision>
	</link>
	<joint name="right_hip" type="spherical">
		<parent link="root" />
		<child link="right_hip" />
		<origin rpy="0 0 0" xyz="0 0 0.130769" />
		<axis xyz="0 0 1" />
	</joint>
	<link name="right_knee">
		<inertial>
			<origin rpy="0 0 0" xyz="0 -0.246154 0" />
			<mass value="3.387097" />
			<inertia ixx="0.003563" ixy="0" ixz="0" iyy="0.003563" iyz="0" izz="0.003563" />
		</inertial>
		<collision>
			<origin rpy="-1.570796 0 0" xyz="0 -0.246154 0" />
			<geometry>
				<capsule length="0.381538" radius="0.061538" />
			</geometry>
		</collision>
	</link>
	<joint name="right_knee" type="revolute">
		<parent link="right_hip" />
		<child link="right_knee" />
		<limit effort="1000.0" lower="-3.14" upper="0." velocity="0.5" />
		<origin rpy="0 0 0" xyz="0 -0.518826 0" />
		<axis xyz="0.000000 0.000000 1.000000" />
	</joint>
	<link name="right_ankle">
		<inertial>
			<origin rpy="0 0 0" xyz="0 -0.027692 0" />
			<mass value="1.129032" />
			<inertia ixx="0.000713" ixy="0" ixz="0" iyy="0.000713" iyz="0" izz="0.000713" />
		</inertial>
		<visual>
			<origin rpy="0 0 0" xyz="0 -0.027692 0" />
			<geometry>
				<box size="0.307692 0.08 0.153846" />
			</geometry>
			<material name="white">
				<color rgba="0.95 0.95 0.95 1" />
			</material>
		</visual>
		<collision>
			<origin rpy="0 0 0" xyz="0 -0.027692 0" />
			<geometry>
				<box size="0.307692 0.08 0.153846" />
			</geometry>
		</collision>
		<visual>
			<origin rpy="0 0 0" xyz="0 -0.027692 -0.043077" />
			<geometry>
				<box size="0.246154 0.024615 0.135385" />
			</geometry>
			<material name="sole_r">
				<color rgba="0.2 0.2 0.22 1" />
			</material>
		</visual>
		<collision>
			<origin rpy="0 0 0" xyz="0 -0.027692 -0.043077" />
			<geometry>
				<box size="0.246154 0.024615 0.135385" />
			</geometry>
		</collision>
	</link>
	<joint name="right_ankle" type="spherical">
		<parent link="right_knee" />
		<child link="right_ankle" />
		<origin rpy="0 0 0" xyz="0 -0.504455 0" />
		<axis xyz="0 0 1" />
	</joint>
	<link name="right_shoulder">
		<inertial>
			<origin rpy="0 0 0" xyz="0 -0.172308 0" />
			<mass value="2.258065" />
			<inertia ixx="0.00285" ixy="0" ixz="0" iyy="0.00285" iyz="0" izz="0.00285" />
		</inertial>
		<collision>
			<origin rpy="-1.570796 0 0" xyz="0 -0.172308 0" />
			<geometry>
				<capsule length="0.221538" radius="0.055385" />
			</geometry>
		</collision>
	</link>
	<joint name="right_shoulder" type="spherical">
		<parent link="chest" />
		<child link="right_shoulder" />
		<origin rpy="0 0 0" xyz="-0.0296 0.299692 0.225366" />
		<axis xyz="0 0 1" />
	</joint>
	<link name="right_elbow">
		<inertial>
			<origin rpy="0 0 0" xyz="0 -0.147692 0" />
			<mass value="1.505376" />
			<inertia ixx="0.001425" ixy="0" ixz="0" iyy="0.001425" iyz="0" izz="0.001425" />
		</inertial>
		<collision>
			<origin rpy="-1.570796 0 0" xyz="0 -0.147692 0" />
			<geometry>
				<capsule length="0.166154" radius="0.049231" />
			</geometry>
		</collision>
	</link>
	<joint name="right_elbow" type="revolute">
		<parent link="right_shoulder" />
		<child link="right_elbow" />
		<limit effort="1000.0" lower="0" upper="3.14" velocity="0.5" />
		<origin rpy="0 0 0" xyz="0 -0.338201 0" />
		<axis xyz="0.000000 0.000000 1.000000" />
	</joint>
	<link name="right_wrist">
		<inertial>
			<origin rpy="0 0 0" xyz="0 0 0" />
			<mass value="0.376344" />
			<inertia ixx="0.000356" ixy="0" ixz="0" iyy="0.000356" iyz="0" izz="0.000356" />
		</inertial>
		<collision>
			<origin rpy="0 0 0" xyz="0 0 0" />
			<geometry>
				<sphere radius="0.049231" />
			</geometry>
		</collision>
	</link>
	<joint name="right_wrist" type="revolute">
		<parent link="right_elbow" />
		<child link="right_wrist" />
		<origin rpy="0 0 0" xyz="0 -0.318704 0" />
		<axis xyz="0 0 1" />
		<limit effort="200" lower="-0.8" upper="0.8" velocity="2" />
	</joint>
	<link name="left_hip">
		<inertial>
			<origin rpy="0 0 0" xyz="0 -0.258462 0" />
			<mass value="6.774194" />
			<inertia ixx="0.007126" ixy="0" ixz="0" iyy="0.007126" iyz="0" izz="0.007126" />
		</inertial>
		<collision>
			<origin rpy="-1.570796 0 0" xyz="0 -0.258462 0" />
			<geometry>
				<capsule length="0.369231" radius="0.067692" />
			</geometry>
		</collision>
	</link>
	<joint name="left_hip" type="spherical">
		<parent link="root" />
		<child link="left_hip" />
		<origin rpy="0 0 0" xyz="0 0 -0.130769" />
		<axis xyz="0 0 1" />
	</joint>
	<link name="left_knee">
		<inertial>
			<origin rpy="0 0 0" xyz="0 -0.246154 0" />
			<mass value="3.387097" />
			<inertia ixx="0.003563" ixy="0" ixz="0" iyy="0.003563" iyz="0" izz="0.003563" />
		</inertial>
		<collision>
			<origin rpy="-1.570796 0 0" xyz="0 -0.246154 0" />
			<geometry>
				<capsule length="0.381538" radius="0.061538" />
			</geometry>
		</collision>
	</link>
	<joint name="left_knee" type="revolute">
		<parent link="left_hip" />
		<child link="left_knee" />
		<limit effort="1000.0" lower="-3.14" upper="0." velocity="0.5" />
		<origin rpy="0 0 0" xyz="0 -0.518826 0" />
		<axis xyz="0.000000 0.000000 1.000000" />
	</joint>
	<link name="left_ankle">
		<inertial>
			<origin rpy="0 0 0" xyz="0 -0.027692 0" />
			<mass value="1.129032" />
			<inertia ixx="0.000713" ixy="0" ixz="0" iyy="0.000713" iyz="0" izz="0.000713" />
		</inertial>
		<visual>
			<origin rpy="0 0 0" xyz="0 -0.027692 0" />
			<geometry>
				<box size="0.307692 0.08 0.153846" />
			</geometry>
			<material name="white_l">
				<color rgba="0.95 0.95 0.95 1" />
			</material>
		</visual>
		<collision>
			<origin rpy="0 0 0" xyz="0 -0.027692 0" />
			<geometry>
				<box size="0.307692 0.08 0.153846" />
			</geometry>
		</collision>
		<visual>
			<origin rpy="0 0 0" xyz="0 -0.027692 -0.043077" />
			<geometry>
				<box size="0.246154 0.024615 0.135385" />
			</geometry>
			<material name="sole_l">
				<color rgba="0.2 0.2 0.22 1" />
			</material>
		</visual>
		<collision>
			<origin rpy="0 0 0" xyz="0 -0.027692 -0.043077" />
			<geometry>
				<box size="0.246154 0.024615 0.135385" />
			</geometry>
		</collision>
	</link>
	<joint name="left_ankle" type="spherical">
		<parent link="left_knee" />
		<child link="left_ankle" />
		<origin rpy="0 0 0" xyz="0 -0.504455 0" />
		<axis xyz="0 0 1" />
	</joint>
	<link name="left_shoulder">
		<inertial>
			<origin rpy="0 0 0" xyz="0 -0.172308 0" />
			<mass value="2.258065" />
			<inertia ixx="0.00285" ixy="0" ixz="0" iyy="0.00285" iyz="0" izz="0.00285" />
		</inertial>
		<collision>
			<origin rpy="-1.570796 0 0" xyz="0 -0.172308 0" />
			<geometry>
				<capsule length="0.221538" radius="0.055385" />
			</geometry>
		</collision>
	</link>
	<joint name="left_shoulder" type="spherical">
		<parent link="chest" />
		<child link="left_shoulder" />
		<origin rpy="0 0 0" xyz="-0.0296 0.299692 -0.225366" />
		<axis xyz="0 0 1" />
	</joint>
	<link name="left_elbow">
		<inertial>
			<origin rpy="0 0 0" xyz="0 -0.147692 0" />
			<mass value="1.505376" />
			<inertia ixx="0.001425" ixy="0" ixz="0" iyy="0.001425" iyz="0" izz="0.001425" />
		</inertial>
		<collision>
			<origin rpy="-1.570796 0 0" xyz="0 -0.147692 0" />
			<geometry>
				<capsule length="0.166154" radius="0.049231" />
			</geometry>
		</collision>
	</link>
	<joint name="left_elbow" type="revolute">
		<parent link="left_shoulder" />
		<child link="left_elbow" />
		<limit effort="1000.0" lower="0" upper="3.14" velocity="0.5" />
		<origin rpy="0 0 0" xyz="0 -0.338201 0" />
		<axis xyz="0.000000 0.000000 1.000000" />
	</joint>
	<link name="left_wrist">
		<inertial>
			<origin rpy="0 0 0" xyz="0 0 0" />
			<mass value="0.376344" />
			<inertia ixx="0.000356" ixy="0" ixz="0" iyy="0.000356" iyz="0" izz="0.000356" />
		</inertial>
		<collision>
			<origin rpy="0 0 0" xyz="0 0 0" />
			<geometry>
				<sphere radius="0.049231" />
			</geometry>
		</collision>
	</link>
	<joint name="left_wrist" type="revolute">
		<parent link="left_elbow" />
		<child link="left_wrist" />
		<origin rpy="0 0 0" xyz="0 -0.318704 0" />
		<axis xyz="0 0 1" />
		<limit effort="200" lower="-0.8" upper="0.8" velocity="2" />
	</joint>
</robot>